Workbook

Sheet Per_15min
A1: Video file | B1: Annotated clip | C1: Site | D1: Location / camera | E1: Date | F1: Bin start | G1: Bin end | H1: Chunk # | I1: Seconds processed | J1: Include (1/0) | K1: AI bicyclists (total) | L1: AI bicyclists bike lane | M1: AI bicyclists sidewalk | N1: AI bicyclists unassigned | O1: GT bicyclists bike lane | P1: GT bicyclists sidewalk | Q1: GT bicyclists (total) | R1: Diff bicyclists (AI-GT) | S1: Abs diff | T1: Matched = MIN(AI,GT) | U1: Flag | V1: AI pedestrians | W1: GT pedestrians | X1: Diff pedestrians (AI-GT) | Y1: AI vehicles
A2: Standard_SCU8OG_2019-07-10_0000.013.mp4 | B2: annotated/colonial_run5/Standard_SCU8OG_2019-07-10_0000.013/Standard_SCU8OG_2019-07-10_0000.013_20190710_1200-1215.mp4 | C2: Colonial North | D2: Colonial - BL Colonial camera (SCU8OG) | E2: 2019-07-10 | F2: 12:00 PM | G2: 12:15 PM | H2: 13 | I2: 900 | J2: =IF(I2>=Metrics!$B$4*Metrics!$B$3,1,0) | K2: 0 | L2: 0 | M2: 0 | N2: 0 | O2: 0 | P2: 0 | Q2: =O2+P2 | R2: =K2-Q2 | S2: =ABS(R2) | T2: =MIN(K2,Q2) | U2: =IF(J2=0,"partial",IF(S2>Metrics!$B$5,"CHECK","ok")) | V2: 0 | W2: 0 | X2: =V2-W2 | Y2: 618
A3: Standard_SCU8OG_2019-07-10_0000.013.mp4 | B3: annotated/colonial_run5/Standard_SCU8OG_2019-07-10_0000.013/Standard_SCU8OG_2019-07-10_0000.013_20190710_1215-1230.mp4 | C3: Colonial North | D3: Colonial - BL Colonial camera (SCU8OG) | E3: 2019-07-10 | F3: 12:15 PM | G3: 12:30 PM | H3: 13 | I3: 900 | J3: =IF(I3>=Metrics!$B$4*Metrics!$B$3,1,0) | K3: 0 | L3: 0 | M3: 0 | N3: 0 | O3: 0 | P3: 0 | Q3: =O3+P3 | R3: =K3-Q3 | S3: =ABS(R3) | T3: =MIN(K3,Q3) | U3: =IF(J3=0,"partial",IF(S3>Metrics!$B$5,"CHECK","ok")) | V3: 0 | W3: 0 | X3: =V3-W3 | Y3: 616
A4: Standard_SCU8OG_2019-07-10_0000.013.mp4 | B4: annotated/colonial_run5/Standard_SCU8OG_2019-07-10_0000.013/Standard_SCU8OG_2019-07-10_0000.013_20190710_1230-1245.mp4 | C4: Colonial North | D4: Colonial - BL Colonial camera (SCU8OG) | E4: 2019-07-10 | F4: 12:30 PM | G4: 12:45 PM | H4: 13 | I4: 900 | J4: =IF(I4>=Metrics!$B$4*Metrics!$B$3,1,0) | K4: 1 | L4: 0 | M4: 0 | N4: 1 | O4: 1 | P4: 0 | Q4: =O4+P4 | R4: =K4-Q4 | S4: =ABS(R4) | T4: =MIN(K4,Q4) | U4: =IF(J4=0,"partial",IF(S4>Metrics!$B$5,"CHECK","ok")) | V4: 0 | W4: 0 | X4: =V4-W4 | Y4: 522
A5: Standard_SCU8OG_2019-07-10_0000.013.mp4 | B5: annotated/colonial_run5/Standard_SCU8OG_2019-07-10_0000.013/Standard_SCU8OG_2019-07-10_0000.013_20190710_1245-1300.mp4 | C5: Colonial North | D5: Colonial - BL Colonial camera (SCU8OG) | E5: 2019-07-10 | F5: 12:45 PM | G5: 01:00 PM | H5: 13 | I5: 899 | J5: =IF(I5>=Metrics!$B$4*Metrics!$B$3,1,0) | K5: 4 | L5: 0 | M5: 0 | N5: 4 | O5: 2 | P5: 0 | Q5: =O5+P5 | R5: =K5-Q5 | S5: =ABS(R5) | T5: =MIN(K5,Q5) | U5: =IF(J5=0,"partial",IF(S5>Metrics!$B$5,"CHECK","ok")) | V5: 1 | W5: 2 | X5: =V5-W5 | Y5: 595
A6: Standard_SCU8OG_2019-07-10_0000.014.mp4 | B6: annotated/colonial_run5/Standard_SCU8OG_2019-07-10_0000.014/Standard_SCU8OG_2019-07-10_0000.014_20190710_1300-1315.mp4 | C6: Colonial North | D6: Colonial - BL Colonial camera (SCU8OG) | E6: 2019-07-10 | F6: 01:00 PM | G6: 01:15 PM | H6: 14 | I6: 900 | J6: =IF(I6>=Metrics!$B$4*Metrics!$B$3,1,0) | K6: 0 | L6: 0 | M6: 0 | N6: 0 | O6: 0 | P6: 0 | Q6: =O6+P6 | R6: =K6-Q6 | S6: =ABS(R6) | T6: =MIN(K6,Q6) | U6: =IF(J6=0,"partial",IF(S6>Metrics!$B$5,"CHECK","ok")) | V6: 1 | W6: 1 | X6: =V6-W6 | Y6: 606
A7: Standard_SCU8OG_2019-07-10_0000.014.mp4 | B7: annotated/colonial_run5/Standard_SCU8OG_2019-07-10_0000.014/Standard_SCU8OG_2019-07-10_0000.014_20190710_1315-1330.mp4 | C7: Colonial North | D7: Colonial - BL Colonial camera (SCU8OG) | E7: 2019-07-10 | F7: 01:15 PM | G7: 01:30 PM | H7: 14 | I7: 900 | J7: =IF(I7>=Metrics!$B$4*Metrics!$B$3,1,0) | K7: 1 | L7: 0 | M7: 0 | N7: 1 | O7: 0 | P7: 0 | Q7: =O7+P7 | R7: =K7-Q7 | S7: =ABS(R7) | T7: =MIN(K7,Q7) | U7: =IF(J7=0,"partial",IF(S7>Metrics!$B$5,"CHECK","ok")) | V7: 0 | W7: 3 | X7: =V7-W7 | Y7: 585
A8: Standard_SCU8OG_2019-07-10_0000.014.mp4 | B8: annotated/colonial_run5/Standard_SCU8OG_2019-07-10_0000.014/Standard_SCU8OG_2019-07-10_0000.014_20190710_1330-1345.mp4 | C8: Colonial North | D8: Colonial - BL Colonial camera (SCU8OG) | E8: 2019-07-10 | F8: 01:30 PM | G8: 01:45 PM | H8: 14 | I8: 900 | J8: =IF(I8>=Metrics!$B$4*Metrics!$B$3,1,0) | K8: 0 | L8: 0 | M8: 0 | N8: 0 | O8: 0 | P8: 1 | Q8: =O8+P8 | R8: =K8-Q8 | S8: =ABS(R8) | T8: =MIN(K8,Q8) | U8: =IF(J8=0,"partial",IF(S8>Metrics!$B$5,"CHECK","ok")) | V8: 2 | W8: 1 | X8: =V8-W8 | Y8: 601
A9: Standard_SCU8OG_2019-07-10_0000.014.mp4 | B9: annotated/colonial_run5/Standard_SCU8OG_2019-07-10_0000.014/Standard_SCU8OG_2019-07-10_0000.014_20190710_1345-1400.mp4 | C9: Colonial North | D9: Colonial - BL Colonial camera (SCU8OG) | E9: 2019-07-10 | F9: 01:45 PM | G9: 02:00 PM | H9: 14 | I9: 898.5 | J9: =IF(I9>=Metrics!$B$4*Metrics!$B$3,1,0) | K9: 0 | L9: 0 | M9: 0 | N9: 0 | O9: 0 | P9: 2 | Q9: =O9+P9 | R9: =K9-Q9 | S9: =ABS(R9) | T9: =MIN(K9,Q9) | U9: =IF(J9=0,"partial",IF(S9>Metrics!$B$5,"CHECK","ok")) | V9: 2 | W9: 1 | X9: =V9-W9 | Y9: 640
A10: Standard_SCU8OG_2019-07-10_0000.022.mp4 | B10: annotated/colonial_run5/Standard_SCU8OG_2019-07-10_0000.022/Standard_SCU8OG_2019-07-10_0000.022_20190710_2100-2115.mp4 | C10: Colonial North | D10: Colonial - BL Colonial camera (SCU8OG) | E10: 2019-07-10 | F10: 09:00 PM | G10: 09:15 PM | H10: 22 | I10: 900 | J10: =IF(I10>=Metrics!$B$4*Metrics!$B$3,1,0) | K10: 0 | L10: 0 | M10: 0 | N10: 0 | O10: 0 | P10: 0 | Q10: =O10+P10 | R10: =K10-Q10 | S10: =ABS(R10) | T10: =MIN(K10,Q10) | U10: =IF(J10=0,"partial",IF(S10>Metrics!$B$5,"CHECK","ok")) | V10: 0 | W10: 1 | X10: =V10-W10 | Y10: 255
A11: Standard_SCU8OG_2019-07-10_0000.022.mp4 | B11: annotated/colonial_run5/Standard_SCU8OG_2019-07-10_0000.022/Standard_SCU8OG_2019-07-10_0000.022_20190710_2115-2130.mp4 | C11: Colonial North | D11: Colonial - BL Colonial camera (SCU8OG) | E11: 2019-07-10 | F11: 09:15 PM | G11: 09:30 PM | H11: 22 | I11: 900 | J11: =IF(I11>=Metrics!$B$4*Metrics!$B$3,1,0) | K11: 0 | L11: 0 | M11: 0 | N11: 0 | O11: 0 | P11: 3 | Q11: =O11+P11 | R11: =K11-Q11 | S11: =ABS(R11) | T11: =MIN(K11,Q11) | U11: =IF(J11=0,"partial",IF(S11>Metrics!$B$5,"CHECK","ok")) | V11: 1 | W11: 2 | X11: =V11-W11 | Y11: 287
A12: Standard_SCU8OG_2019-07-10_0000.022.mp4 | B12: annotated/colonial_run5/Standard_SCU8OG_2019-07-10_0000.022/Standard_SCU8OG_2019-07-10_0000.022_20190710_2130-2145.mp4 | C12: Colonial North | D12: Colonial - BL Colonial camera (SCU8OG) | E12: 2019-07-10 | F12: 09:30 PM | G12: 09:45 PM | H12: 22 | I12: 900 | J12: =IF(I12>=Metrics!$B$4*Metrics!$B$3,1,0) | K12: 0 | L12: 0 | M12: 0 | N12: 0 | O12: 0 | P12: 0 | Q12: =O12+P12 | R12: =K12-Q12 | S12: =ABS(R12) | T12: =MIN(K12,Q12) | U12: =IF(J12=0,"partial",IF(S12>Metrics!$B$5,"CHECK","ok")) | V12: 0 | W12: 1 | X12: =V12-W12 | Y12: 285
A13: Standard_SCU8OG_2019-07-10_0000.022.mp4 | B13: annotated/colonial_run5/Standard_SCU8OG_2019-07-10_0000.022/Standard_SCU8OG_2019-07-10_0000.022_20190710_2145-2200.mp4 | C13: Colonial North | D13: Colonial - BL Colonial camera (SCU8OG) | E13: 2019-07-10 | F13: 09:45 PM | G13: 10:00 PM | H13: 22 | I13: 899.4 | J13: =IF(I13>=Metrics!$B$4*Metrics!$B$3,1,0) | K13: 0 | L13: 0 | M13: 0 | N13: 0 | O13: 0 | P13: 0 | Q13: =O13+P13 | R13: =K13-Q13 | S13: =ABS(R13) | T13: =MIN(K13,Q13) | U13: =IF(J13=0,"partial",IF(S13>Metrics!$B$5,"CHECK","ok")) | V13: 0 | W13: 3 | X13: =V13-W13 | Y13: 311

Sheet Per_hour
A1: Chunk # | B1: Video file | C1: Hour start | D1: Bins included | E1: AI bicyclists | F1: GT bicyclists | G1: Diff (AI-GT) | H1: AI pedestrians | I1: GT pedestrians | J1: Diff pedestrians | K1: AI vehicles
A2: 13 | B2: Standard_SCU8OG_2019-07-10_0000.013.mp4 | C2: 2019-07-10 12:00 PM | D2: =SUMPRODUCT((Per_15min!$H$2:$H$13=A2)*Per_15min!$J$2:$J$13) | E2: =SUMPRODUCT((Per_15min!$H$2:$H$13=A2)*Per_15min!$J$2:$J$13*Per_15min!$K$2:$K$13) | F2: =SUMPRODUCT((Per_15min!$H$2:$H$13=A2)*Per_15min!$J$2:$J$13*Per_15min!$Q$2:$Q$13) | G2: =E2-F2 | H2: =SUMPRODUCT((Per_15min!$H$2:$H$13=A2)*Per_15min!$J$2:$J$13*Per_15min!$V$2:$V$13) | I2: =SUMPRODUCT((Per_15min!$H$2:$H$13=A2)*Per_15min!$J$2:$J$13*Per_15min!$W$2:$W$13) | J2: =H2-I2 | K2: =SUMPRODUCT((Per_15min!$H$2:$H$13=A2)*Per_15min!$J$2:$J$13*Per_15min!$Y$2:$Y$13)
A3: 14 | B3: Standard_SCU8OG_2019-07-10_0000.014.mp4 | C3: 2019-07-10 01:00 PM | D3: =SUMPRODUCT((Per_15min!$H$2:$H$13=A3)*Per_15min!$J$2:$J$13) | E3: =SUMPRODUCT((Per_15min!$H$2:$H$13=A3)*Per_15min!$J$2:$J$13*Per_15min!$K$2:$K$13) | F3: =SUMPRODUCT((Per_15min!$H$2:$H$13=A3)*Per_15min!$J$2:$J$13*Per_15min!$Q$2:$Q$13) | G3: =E3-F3 | H3: =SUMPRODUCT((Per_15min!$H$2:$H$13=A3)*Per_15min!$J$2:$J$13*Per_15min!$V$2:$V$13) | I3: =SUMPRODUCT((Per_15min!$H$2:$H$13=A3)*Per_15min!$J$2:$J$13*Per_15min!$W$2:$W$13) | J3: =H3-I3 | K3: =SUMPRODUCT((Per_15min!$H$2:$H$13=A3)*Per_15min!$J$2:$J$13*Per_15min!$Y$2:$Y$13)
A4: 22 | B4: Standard_SCU8OG_2019-07-10_0000.022.mp4 | C4: 2019-07-10 09:00 PM | D4: =SUMPRODUCT((Per_15min!$H$2:$H$13=A4)*Per_15min!$J$2:$J$13) | E4: =SUMPRODUCT((Per_15min!$H$2:$H$13=A4)*Per_15min!$J$2:$J$13*Per_15min!$K$2:$K$13) | F4: =SUMPRODUCT((Per_15min!$H$2:$H$13=A4)*Per_15min!$J$2:$J$13*Per_15min!$Q$2:$Q$13) | G4: =E4-F4 | H4: =SUMPRODUCT((Per_15min!$H$2:$H$13=A4)*Per_15min!$J$2:$J$13*Per_15min!$V$2:$V$13) | I4: =SUMPRODUCT((Per_15min!$H$2:$H$13=A4)*Per_15min!$J$2:$J$13*Per_15min!$W$2:$W$13) | J4: =H4-I4 | K4: =SUMPRODUCT((Per_15min!$H$2:$H$13=A4)*Per_15min!$J$2:$J$13*Per_15min!$Y$2:$Y$13)
A5: Total | D5: =SUM(D2:D4) | E5: =SUM(E2:E4) | F5: =SUM(F2:F4) | G5: =SUM(G2:G4) | H5: =SUM(H2:H4) | I5: =SUM(I2:I4) | J5: =SUM(J2:J4) | K5: =SUM(K2:K4)

Sheet Metrics
A1: Validation metrics - Colonial North - run colonial_run5
A2: Blue/yellow cells are inputs; everything else is a formula over Per_15min (only rows with Include = 1).
A3: Bin length (seconds) | B3: 900 | C3: GT is counted in 15-minute bins
A4: Min coverage of a bin to include it | B4: 0.98 | C4: bins processed for < 98% of their length (e.g. a smoke test) are excluded
A5: Flag a bin if |AI - GT| bicyclists exceeds | B5: 2 | C5: tolerance for the CHECK flag; a judgement call, edit freely
A7: BICYCLISTS (bike lane + sidewalk, per 15-min bin)
A8: Bins evaluated | B8: =SUM(Per_15min!$J$2:$J$13)
A9: Total AI | B9: =SUMPRODUCT(Per_15min!$J$2:$J$13,Per_15min!$K$2:$K$13)
A10: Total GT | B10: =SUMPRODUCT(Per_15min!$J$2:$J$13,Per_15min!$Q$2:$Q$13)
A11: Bias: mean (AI - GT) per bin (+ = overcount) | B11: =IF(B8=0,"",SUMPRODUCT(Per_15min!$J$2:$J$13,Per_15min!$R$2:$R$13)/B8)
A12: MAE: mean |AI - GT| per bin | B12: =IF(B8=0,"",SUMPRODUCT(Per_15min!$J$2:$J$13,Per_15min!$S$2:$S$13)/B8)
A13: RMSE per bin | B13: =IF(B8=0,"",SQRT(SUMPRODUCT(Per_15min!$J$2:$J$13,Per_15min!$R$2:$R$13,Per_15min!$R$2:$R$13)/B8))
A14: WAPE: sum|err| / sum GT | B14: =IF(B10=0,"",SUMPRODUCT(Per_15min!$J$2:$J$13,Per_15min!$S$2:$S$13)/B10)
A15: Share of bins within +-1 | B15: =IF(B8=0,"",SUMPRODUCT(Per_15min!$J$2:$J$13,--(Per_15min!$S$2:$S$13<=1))/B8)
A16: Share of bins within +-2 | B16: =IF(B8=0,"",SUMPRODUCT(Per_15min!$J$2:$J$13,--(Per_15min!$S$2:$S$13<=2))/B8)
A17: Pearson r (AI vs GT per bin) | B17: =IFERROR((B8*SUMPRODUCT(Per_15min!$J$2:$J$13,Per_15min!$K$2:$K$13,Per_15min!$Q$2:$Q$13)-B9*B10)/SQRT((B8*SUMPRODUCT(Per_15min!$J$2:$J$13,Per_15min!$K$2:$K$13,Per_15min!$K$2:$K$13)-B9^2)*(B8*SUMPRODUCT(Per_15min!$J$2:$J$13,Per_15min!$Q$2:$Q$13,Per_15min!$Q$2:$Q$13)-B10^2)),"n/a")
A18: Count-matched precision (approx.) = sum MIN(AI,GT) / sum AI | B18: =IF(B9=0,"",SUMPRODUCT(Per_15min!$J$2:$J$13,Per_15min!$T$2:$T$13)/B9)
A19: Count-matched recall (approx.) = sum MIN(AI,GT) / sum GT | B19: =IF(B10=0,"",SUMPRODUCT(Per_15min!$J$2:$J$13,Per_15min!$T$2:$T$13)/B10)
A20: Count-matched F1 (approx.) | B20: =IFERROR(2*B18*B19/(B18+B19),"")
A21: Note: there is no per-person ground truth, so precision/recall are count-based approximations (a missed rider in one bin cancelling a false rider in the same bin is not detected). Use the annotated clips for true error types.
A23: PEDESTRIANS (North channels; reported, not the main target)
A24: Total AI | B24: =SUMPRODUCT(Per_15min!$J$2:$J$13,Per_15min!$V$2:$V$13)
A25: Total GT | B25: =SUMPRODUCT(Per_15min!$J$2:$J$13,Per_15min!$W$2:$W$13)
A26: Bias: mean (AI - GT) per bin | B26: =IF(B8=0,"",SUMPRODUCT(Per_15min!$J$2:$J$13,Per_15min!$X$2:$X$13)/B8)
A27: MAE per bin | B27: =IF(B8=0,"",SUMPRODUCT(Per_15min!$J$2:$J$13,ABS(Per_15min!$X$2:$X$13))/B8)
A28: BIKE LANE vs SIDEWALK split (needs a zones file; 0 AI = zones not set)
A29: AI bicyclists bike lane | B29: =SUMPRODUCT(Per_15min!$J$2:$J$13,Per_15min!$L$2:$L$13)
A30: GT bicyclists bike lane | B30: =SUMPRODUCT(Per_15min!$J$2:$J$13,Per_15min!$O$2:$O$13)
A31: AI bicyclists sidewalk | B31: =SUMPRODUCT(Per_15min!$J$2:$J$13,Per_15min!$M$2:$M$13)
A32: GT bicyclists sidewalk | B32: =SUMPRODUCT(Per_15min!$J$2:$J$13,Per_15min!$P$2:$P$13)
A33: AI bicyclists unassigned (no zone) | B33: =SUMPRODUCT(Per_15min!$J$2:$J$13,Per_15min!$N$2:$N$13)
A35: DETECTOR vs X-CLIP LABELS (counted tracks; rows = RT-DETR label, columns = X-CLIP label)
B36: X-CLIP: BICYCLIST | C36: X-CLIP: PEDESTRIAN
A37: RT-DETR: cyclist | B37: =COUNTIFS(Tracks!$I$2:$I$14,"cyclist",Tracks!$L$2:$L$14,"BICYCLIST") | C37: =COUNTIFS(Tracks!$I$2:$I$14,"cyclist",Tracks!$L$2:$L$14,"PEDESTRIAN")
A38: RT-DETR: person | B38: =COUNTIFS(Tracks!$I$2:$I$14,"person",Tracks!$L$2:$L$14,"BICYCLIST") | C38: =COUNTIFS(Tracks!$I$2:$I$14,"person",Tracks!$L$2:$L$14,"PEDESTRIAN")
A39: Agreement rate (counted tracks) | B39: =IFERROR(COUNTIF(Tracks!$O$2:$O$14,"yes")/COUNTIF(Tracks!$O$2:$O$14,"<>n/a"),"n/a")
A40: 'cyclist'/'person' are the detector's own classes; the X-CLIP label is the final label used for counting.

Sheet Tracks
A1: Video file | B1: Annotated clip | C1: Site | D1: Date | E1: First seen | F1: Last seen | G1: 15-min bin | H1: Track ID | I1: RT-DETR label (detector) | J1: RT-DETR mean conf | K1: % detections classed 'cyclist' | L1: X-CLIP label | M1: X-CLIP P(bicyclist) | N1: X-CLIP P(pedestrian) | O1: Labels agree? | P1: Facility (zone) | Q1: Seconds visible | R1: Net movement (px)
A2: Standard_SCU8OG_2019-07-10_0000.013.mp4 | B2: annotated/colonial_run5/Standard_SCU8OG_2019-07-10_0000.013/Standard_SCU8OG_2019-07-10_0000.013_20190710_1230-1245.mp4 | C2: Colonial North | D2: 2019-07-10 | E2: 12:40:14 | F2: 12:40:23 | G2: 12:30 PM | H2: 4 | I2: person | J2: 0.651 | K2: 49.4 | L2: BICYCLIST | M2: 0.747 | N2: 0.253 | O2: =IF(I2="n/a","n/a",IF(OR(AND(I2="cyclist",L2="BICYCLIST"),AND(I2="person",L2="PEDESTRIAN")),"yes","NO")) | P2: unassigned | Q2: 8.98 | R2: 571.3
A3: Standard_SCU8OG_2019-07-10_0000.013.mp4 | B3: annotated/colonial_run5/Standard_SCU8OG_2019-07-10_0000.013/Standard_SCU8OG_2019-07-10_0000.013_20190710_1245-1300.mp4 | C3: Colonial North | D3: 2019-07-10 | E3: 12:45:40 | F3: 12:45:56 | G3: 12:45 PM | H3: 5 | I3: person | J3: 0.555 | K3: 44.7 | L3: BICYCLIST | M3: 0.645 | N3: 0.355 | O3: =IF(I3="n/a","n/a",IF(OR(AND(I3="cyclist",L3="BICYCLIST"),AND(I3="person",L3="PEDESTRIAN")),"yes","NO")) | P3: unassigned | Q3: 9.11 | R3: 657
A4: Standard_SCU8OG_2019-07-10_0000.013.mp4 | B4: annotated/colonial_run5/Standard_SCU8OG_2019-07-10_0000.013/Standard_SCU8OG_2019-07-10_0000.013_20190710_1245-1300.mp4 | C4: Colonial North | D4: 2019-07-10 | E4: 12:53:07 | F4: 12:53:13 | G4: 12:45 PM | H4: 8 | I4: person | J4: 0.569 | K4: 46.4 | L4: BICYCLIST | M4: 0.787 | N4: 0.213 | O4: =IF(I4="n/a","n/a",IF(OR(AND(I4="cyclist",L4="BICYCLIST"),AND(I4="person",L4="PEDESTRIAN")),"yes","NO")) | P4: unassigned | Q4: 3.67 | R4: 355
A5: Standard_SCU8OG_2019-07-10_0000.013.mp4 | B5: annotated/colonial_run5/Standard_SCU8OG_2019-07-10_0000.013/Standard_SCU8OG_2019-07-10_0000.013_20190710_1245-1300.mp4 | C5: Colonial North | D5: 2019-07-10 | E5: 12:53:45 | F5: 12:53:52 | G5: 12:45 PM | H5: 10 | I5: person | J5: 0.682 | K5: 45 | L5: BICYCLIST | M5: 0.788 | N5: 0.212 | O5: =IF(I5="n/a","n/a",IF(OR(AND(I5="cyclist",L5="BICYCLIST"),AND(I5="person",L5="PEDESTRIAN")),"yes","NO")) | P5: unassigned | Q5: 6.97 | R5: 469.2
A6: Standard_SCU8OG_2019-07-10_0000.013.mp4 | B6: annotated/colonial_run5/Standard_SCU8OG_2019-07-10_0000.013/Standard_SCU8OG_2019-07-10_0000.013_20190710_1245-1300.mp4 | C6: Colonial North | D6: 2019-07-10 | E6: 12:54:53 | F6: 12:55:03 | G6: 12:45 PM | H6: 11 | I6: person | J6: 0.529 | K6: 0 | L6: PEDESTRIAN | M6: 0.182 | N6: 0.818 | O6: =IF(I6="n/a","n/a",IF(OR(AND(I6="cyclist",L6="BICYCLIST"),AND(I6="person",L6="PEDESTRIAN")),"yes","NO")) | P6: unassigned | Q6: 4.84 | R6: 29
A7: Standard_SCU8OG_2019-07-10_0000.013.mp4 | B7: annotated/colonial_run5/Standard_SCU8OG_2019-07-10_0000.013/Standard_SCU8OG_2019-07-10_0000.013_20190710_1245-1300.mp4 | C7: Colonial North | D7: 2019-07-10 | E7: 12:56:16 | F7: 12:56:38 | G7: 12:45 PM | H7: 13 | I7: person | J7: 0.724 | K7: 6.6 | L7: BICYCLIST | M7: 0.648 | N7: 0.352 | O7: =IF(I7="n/a","n/a",IF(OR(AND(I7="cyclist",L7="BICYCLIST"),AND(I7="person",L7="PEDESTRIAN")),"yes","NO")) | P7: unassigned | Q7: 18.59 | R7: 248.7
A8: Standard_SCU8OG_2019-07-10_0000.014.mp4 | B8: annotated/colonial_run5/Standard_SCU8OG_2019-07-10_0000.014/Standard_SCU8OG_2019-07-10_0000.014_20190710_1300-1315.mp4 | C8: Colonial North | D8: 2019-07-10 | E8: 13:05:25 | F8: 13:05:48 | G8: 01:00 PM | H8: 1 | I8: person | J8: 0.63 | K8: 0 | L8: PEDESTRIAN | M8: 0.32 | N8: 0.68 | O8: =IF(I8="n/a","n/a",IF(OR(AND(I8="cyclist",L8="BICYCLIST"),AND(I8="person",L8="PEDESTRIAN")),"yes","NO")) | P8: unassigned | Q8: 20.19 | R8: 364.1
A9: Standard_SCU8OG_2019-07-10_0000.014.mp4 | B9: annotated/colonial_run5/Standard_SCU8OG_2019-07-10_0000.014/Standard_SCU8OG_2019-07-10_0000.014_20190710_1315-1330.mp4 | C9: Colonial North | D9: 2019-07-10 | E9: 13:17:45 | F9: 13:18:13 | G9: 01:15 PM | H9: 2 | I9: person | J9: 0.448 | K9: 6 | L9: BICYCLIST | M9: 0.561 | N9: 0.439 | O9: =IF(I9="n/a","n/a",IF(OR(AND(I9="cyclist",L9="BICYCLIST"),AND(I9="person",L9="PEDESTRIAN")),"yes","NO")) | P9: unassigned | Q9: 11.08 | R9: 241
A10: Standard_SCU8OG_2019-07-10_0000.014.mp4 | B10: annotated/colonial_run5/Standard_SCU8OG_2019-07-10_0000.014/Standard_SCU8OG_2019-07-10_0000.014_20190710_1330-1345.mp4 | C10: Colonial North | D10: 2019-07-10 | E10: 13:37:12 | F10: 13:37:19 | G10: 01:30 PM | H10: 11 | I10: person | J10: 0.498 | K10: 0 | L10: PEDESTRIAN | M10: 0.205 | N10: 0.795 | O10: =IF(I10="n/a","n/a",IF(OR(AND(I10="cyclist",L10="BICYCLIST"),AND(I10="person",L10="PEDESTRIAN")),"yes","NO")) | P10: unassigned | Q10: 4.14 | R10: 26.2
A11: Standard_SCU8OG_2019-07-10_0000.014.mp4 | B11: annotated/colonial_run5/Standard_SCU8OG_2019-07-10_0000.014/Standard_SCU8OG_2019-07-10_0000.014_20190710_1330-1345.mp4 | C11: Colonial North | D11: 2019-07-10 | E11: 13:41:40 | F11: 13:41:46 | G11: 01:30 PM | H11: 13 | I11: person | J11: 0.553 | K11: 0 | L11: PEDESTRIAN | M11: 0.103 | N11: 0.897 | O11: =IF(I11="n/a","n/a",IF(OR(AND(I11="cyclist",L11="BICYCLIST"),AND(I11="person",L11="PEDESTRIAN")),"yes","NO")) | P11: unassigned | Q11: 3.7 | R11: 45.7
A12: Standard_SCU8OG_2019-07-10_0000.014.mp4 | B12: annotated/colonial_run5/Standard_SCU8OG_2019-07-10_0000.014/Standard_SCU8OG_2019-07-10_0000.014_20190710_1345-1400.mp4 | C12: Colonial North | D12: 2019-07-10 | E12: 13:54:18 | F12: 13:54:27 | G12: 01:45 PM | H12: 15 | I12: person | J12: 0.489 | K12: 10.7 | L12: PEDESTRIAN | M12: 0.494 | N12: 0.506 | O12: =IF(I12="n/a","n/a",IF(OR(AND(I12="cyclist",L12="BICYCLIST"),AND(I12="person",L12="PEDESTRIAN")),"yes","NO")) | P12: unassigned | Q12: 1.87 | R12: 335.6
A13: Standard_SCU8OG_2019-07-10_0000.014.mp4 | B13: annotated/colonial_run5/Standard_SCU8OG_2019-07-10_0000.014/Standard_SCU8OG_2019-07-10_0000.014_20190710_1345-1400.mp4 | C13: Colonial North | D13: 2019-07-10 | E13: 13:58:20 | F13: 13:58:31 | G13: 01:45 PM | H13: 21 | I13: person | J13: 0.599 | K13: 1.9 | L13: PEDESTRIAN | M13: 0.294 | N13: 0.706 | O13: =IF(I13="n/a","n/a",IF(OR(AND(I13="cyclist",L13="BICYCLIST"),AND(I13="person",L13="PEDESTRIAN")),"yes","NO")) | P13: unassigned | Q13: 6.97 | R13: 74.4
A14: Standard_SCU8OG_2019-07-10_0000.022.mp4 | B14: annotated/colonial_run5/Standard_SCU8OG_2019-07-10_0000.022/Standard_SCU8OG_2019-07-10_0000.022_20190710_2115-2130.mp4 | C14: Colonial North | D14: 2019-07-10 | E14: 21:29:28 | F14: 21:29:29 | G14: 09:15 PM | H14: 8 | I14: cyclist | J14: 0.613 | K14: 100 | L14: PEDESTRIAN | M14: 0.409 | N14: 0.591 | O14: =IF(I14="n/a","n/a",IF(OR(AND(I14="cyclist",L14="BICYCLIST"),AND(I14="person",L14="PEDESTRIAN")),"yes","NO")) | P14: unassigned | Q14: 1 | R14: 269.1

Sheet Run_Log
A1: RUN SUMMARY
A2: Run name | B2: colonial_run5
A3: Site / location | B3: Colonial North - Colonial - BL Colonial camera (SCU8OG)
A4: Video session start (camera clock) | B4: 2019-07-10 00:00:00 (chunk .001); verified from on-screen clock on .001 = 2019-07-10 12:00:00 AM, .008 = 7:00:01 AM, .025 = 2019-07-11 12:00:01 AM
A5: Chunks processed | B5: 3: [13, 14, 22]
A6: Chunks expected | B6: 3 (13,14,22); missing: none
A7: Videos merged | B7: 0 - each hourly mp4 is processed on its own and the results are joined by clock time; a rider crossing an hour boundary is split across two chunks (rare)
A8: Total video duration processed | B8: 3.00 h
A9: 15-min bins in workbook | B9: 12 (12 evaluated, 0 partial/excluded)
A10: Ground truth file | B10: /orange/xiangyan/rithika/vision/vision3/best/test_colonial/ground_truth/Colonial_North_676806_07-10-2019.xls
A11: Weights | B11: /orange/xiangyan/rithika/vision/vision3/runs/detect/finetune_runs/rtdetr_v3/weights/best.pt
A12: Total runtime (sum over chunks) | B12: 356.6 min
A14: CHECKS
A15: check 1 | B15: Bicycles channels used: ['North Bike Lane', 'North Sidewalk', 'North Bike Lane', 'North Sidewalk'] -> bike-lane cols [1, 3], sidewalk cols [2, 4]
A16: check 2 | B16: Bin labels are consecutive 15-min steps starting 12:00 AM: YES
A17: check 3 | B17: GT bicyclists, all 192 bins of the .xls (48 h): 89
A18: check 4 | B18: GT CSV total for Colonial North: 89 -> MATCHES .xls
A19: check 5 | B19: video_site_mapping: folder=BL Colonial, gt_cyclist_count=89, n_mp4_chunks=48 -> GT is a 89-count over 48 h of bins; chunk count consistent with the 192 GT bins
A21: WARNINGS
A22: warning 1 | B22: chunk 13: streamed clip header (provisional) differs from the final count in 2 bin(s): bin 49 header {'bic': 0, 'ped': 0, 'veh': 617} vs final {'bic': 0, 'ped': 0, 'veh': 616}; bin 50 header {'bic': 1, 'ped': 0, 'veh': 523} vs final {'bic': 1, 'ped': 0, 'veh': 522} -> the workbook uses the FINAL counts
A23: warning 2 | B23: chunk 22: starts 2019-07-10 21:00:00 but previous processed chunk ends 2019-07-10 13:59:58.500000 (non-adjacent chunks)
A25: CHUNK 013 Standard_SCU8OG_2019-07-10_0000.013.mp4
A26: clip start (clock) | B26: 2019-07-10 12:00:00
A27: duration container / processed (s) | B27: 3599.0 / 3599.0
A28: frames processed / header | B28: 107862 / 107862 (fps 29.97, 720x480)
A29: final counts (AI) | B29: bicyclists 5, pedestrians 1, vehicles 2351
A30: params | B30: imgsz 1280, det_conf 0.25, track_thr 0.25, person_min_sec 3.0, stride 3, zones None
A31: runtime / device | B31: 6936.4 s / cuda
A32: streamed clips | B32: True; bins streamed: [48, 49, 50]
A33: annotated clips | B33: annotated/colonial_run5/Standard_SCU8OG_2019-07-10_0000.013/Standard_SCU8OG_2019-07-10_0000.013_20190710_1200-1215.mp4, annotated/colonial_run5/Standard_SCU8OG_2019-07-10_0000.013/Standard_SCU8OG_2019-07-10_0000.013_20190710_1215-1230.mp4, annotated/colonial_run5/Standard_SCU8OG_2019-07-10_0000.013/Standard_SCU8OG_2019-07-10_0000.013_20190710_1230-1245.mp4, annotated/colonial_run5/Standard_SCU8OG_2019-07-10_0000.013/Standard_SCU8OG_2019-07-10_0000.013_20190710_1245-1300.mp4
A34: finished | B34: 2026-10-05T12:47:46
A36: CHUNK 014 Standard_SCU8OG_2019-07-10_0000.014.mp4
A37: clip start (clock) | B37: 2019-07-10 13:00:00
A38: duration container / processed (s) | B38: 3598.5 / 3598.5
A39: frames processed / header | B39: 107847 / 107847 (fps 29.97, 720x480)
A40: final counts (AI) | B40: bicyclists 1, pedestrians 5, vehicles 2432
A41: params | B41: imgsz 1280, det_conf 0.25, track_thr 0.25, person_min_sec 3.0, stride 3, zones None
A42: runtime / device | B42: 7456.2 s / cuda
A43: streamed clips | B43: True; bins streamed: [52, 53, 54]
A44: annotated clips | B44: annotated/colonial_run5/Standard_SCU8OG_2019-07-10_0000.014/Standard_SCU8OG_2019-07-10_0000.014_20190710_1300-1315.mp4, annotated/colonial_run5/Standard_SCU8OG_2019-07-10_0000.014/Standard_SCU8OG_2019-07-10_0000.014_20190710_1315-1330.mp4, annotated/colonial_run5/Standard_SCU8OG_2019-07-10_0000.014/Standard_SCU8OG_2019-07-10_0000.014_20190710_1330-1345.mp4, annotated/colonial_run5/Standard_SCU8OG_2019-07-10_0000.014/Standard_SCU8OG_2019-07-10_0000.014_20190710_1345-1400.mp4
...
